<!-- TOC -->

- [概念](#概念)
- [体系结构](#体系结构)
    - [Throwable](#throwable)
    - [Error](#error)
    - [Exception](#exception)
    - [RunTimeException](#runtimeexception)
    - [检查异常和非检查异常](#检查异常和非检查异常)
- [异常处理](#异常处理)
    - [Java内部异常处理](#java内部异常处理)
    - [try-catch-finally](#try-catch-finally)
    - [throws](#throws)
- [自定义异常](#自定义异常)

<!-- /TOC -->
## 概念
java中的异常处理是**基于面向对象**的一种运行态错误处理机制，通过对异常信息的封装实现对用户非法操作、参数设置异常、硬件系统异常，运行时网络状态更换等在运行态中可能出现的异常信息的处理机制。

当发生异常情况时，一个代表该异常的对象被创建并且在导致该异常的方法中被抛出，而该方法可以选择自己处理异常或者传递该异常。

## 体系结构
Java异常层次结构图如下图所示：
![异常机制](https://github.com/ChenLiang-Vic/Personal-notes/blob/master/javaSE/img/%E5%BC%82%E5%B8%B8%E6%9C%BA%E5%88%B6.png)

### Throwable
Throwable类在异常类的层次结构的顶层，可以用来表示任何可以作为异常抛出的类。

Throwable类分为两种:Error和Exception

### Error
Error类以及他的子类，一般是编译或者系统性的错误,JVM 无法处理，如OutOfMemorry内存溢出异常等。我们无法通过程序处理，所以主要学习Exception异常。

### Exception
Exception以及他的子类，代表程序运行时的各种不期望发生的事件。可以被Java异常处理机制使用，是异常处理的核心。

### RunTimeException
运行时异常。javac在编译时，不会提示和发现这样的异常，不要求在程序处理这些异常。对于这些异常，我们应该修正代码，而不是去通过异常处理器处理 。这样的异常发生的原因多半是代码写的有问题。

常见异常：
- 除0错误ArithmeticException
- 错误的强制类型转换错误ClassCastException，
- 数组索引越界ArrayIndexOutOfBoundsException
- 空指针NullPointerException等。

### 检查异常和非检查异常

**非检查异常**
Error和RuntimeException以及他们的子类。在编译阶段不会出现异常可以编译通过，而在运行阶段出现异常。比如上面常见的空指针NullPointerException等。

**检查异常**
除了Error和RuntimeException的其它异常。javac强制要求程序员为这样的异常做预备处理工作（使用try…catch…finally或者throws）否则编译不会通过。

常见异常：SQLException , IOException,ClassNotFoundException 等


## 异常处理
### Java内部异常处理
java内部已经提供许多标准异常类，当程序出现异常时，如果自己没有处理，java会自动处理异常，但是仅仅是抛出异常，而且在程序异常处停止程序运行，并不会继续执行之后的代码。

```java
public class Demo {
    public static void main(String[] args) {
        int a = 1;
        System.out.println(a/0);
        System.out.println(a);
    } 
}
```
可以看到程序执行1/0异常后抛出ArithmeticException异常后即终止，没有执行下面的输出a命令。

### try-catch-finally
```java
try{
可能发生异常的代码块
}catch（可以捕获的异常1）{
处理异常1的代码
}catch（可以捕获的异常2）{
处理异常2的代码
}finally{
处理完所有异常后一定会执行的代码。
如果没有出现异常，最终也会执行这行代码
}
```
注意：
- 每一个catch块用于处理一个异常。异常匹配是按照catch块的顺序从上往下寻找的，只有第一个匹配的catch会得到执行。匹配时，不仅运行精确匹配，也支持父类匹配，因此，如果同一个try块下的多个catch异常类型有父子关系，应该**将子类异常放在前面，父类异常放在后面，这样保证每个catch块都有存在的意义**。
- finally块不管异常是否发生，只要对应的try执行了，则它一定也执行。只有一种方法让finally块不执行：System.exit()。因此finally块通常用来做资源释放操作：关闭文件，关闭数据库连接等等。

```java
public class Demo {
    public static void main(String[] args){
        int[] a = {1,2,3};
        //索引越界是运行时异常,可以不用try-catch 这里只是演示
        try{
            System.out.println(a[3]); //索引越界
        }catch (ArrayIndexOutOfBoundsException ae){
            //默认调用的是printStackTrace()方法
            ae.printStackTrace();
            //结果如下
            //java.lang.ArrayIndexOutOfBoundsException: 3
            //	at com.company.basealgorithm.Demo.main(Demo.java:8)
        }
    }
    }
```

### throws
throws是另一种处理异常的方式，它直接将异常抛出。对于编译时期的异常如果不做异常处理编译就无法通过，执行该异常处理后，当发生异常时会将异常类显示在控制台上。

采取这种异常处理的原因可能是：方法本身不知道如何处理这样的异常，或者说让调用者处理更好，调用者需要为可能发生的异常负责。

```java
public class Demo {
    public static void main(String[] args) throws ArrayIndexOutOfBoundsException{
        int[] a = {1,2,3};
        System.out.println(a[3]); //索引越界
    }
}
```

## 自定义异常
java中提供的标准异常无法充分描述问题，或者是项目特有的异常，需要我们自定义异常类。

如果要自定义异常类，则扩展Exception类即可，因此这样的自定义异常都属于检查异常（checked exception）。如果要自定义非检查异常，则扩展自RuntimeException。

按照国际惯例，自定义的异常应该总是包含如下的构造函数：

- 一个无参构造函数
- 一个带有String参数的构造函数，并传递给父类的构造函数。
- 一个带有String参数和Throwable参数，并都传递给父类构造函数
- 一个带有Throwable 参数的构造函数，并传递给父类的构造函数。

比如IOException
```java
public class IOException extends Exception
{
    static final long serialVersionUID = 7818375828146090155L;
 
    public IOException()
    {
        super();
    }
 
    public IOException(String message)
    {
        super(message);
    }
 
    public IOException(String message, Throwable cause)
    {
        super(message, cause);
    }
 
    public IOException(Throwable cause)
    {
        super(cause);
    }
}
```
自定义异常
```java
public class MyAgeException extends Exception {
    public MyAgeException() {
    }

    public MyAgeException(String message) {
        super(message);
    }

    public MyAgeException(String message, Throwable cause) {
        super(message, cause);
    }

    public MyAgeException(Throwable cause) {
        super(cause);
    }
}
```
使用自定义异常
```java
public class People {
    private int age;

    public People() {
    }

    public int getAge() {
        return age;
    }

    public void setAge(int age) throws MyAgeException {  //这里我给throws出去了,也可以直接try-catch
        if(age<0||age>150){
            throw new MyAgeException("年龄错误");
        }
        this.age = age;
    }
}
```
测试
```java
public class Demo {
	public static void main(String[] args) throws MyAgeException {
		People p = new People();
		p.setAge(200);  /
	}
}
```
直接编译不通过throws出去后结果
```java
Exception in thread "main" com.company.basealgorithm.MyAgeException: 年龄错误
	at com.company.basealgorithm.People.setAge(People.java:16)
	at com.company.basealgorithm.Demo.main(Demo.java:6)
```

**throws和throw的区别**
![throws和throw的区别](https://github.com/ChenLiang-Vic/Personal-notes/blob/master/javaSE/img/throws%E5%92%8Cthrow%E7%9A%84%E5%8C%BA%E5%88%AB.png)